<?xml version="1.0" ?>
<robot name="rover">
    <!-- main center object -->
    <link name="base_link">
        <visual>
            <geometry>
                <box size="0.4 0.35 0.075"/>
            </geometry>
            <material name="gray">
                <color rgba="0.2 0.2 0.2 1"/>
            </material>
        </visual>
        <inertial>
            <mass value="2"/>
            <inertia ixx="0.04" ixy="0.0" ixz="0.0" iyy="0.17" iyz="0.0" izz="0.25" />
        </inertial>
        <collision>
            <geometry>
                <box size="0.4 0.35 0.1"/>
            </geometry>
        </collision>
    </link>

    <!-- Robot Footprint -->
    <link name="base_footprint"/>

    <joint name="base_joint" type="fixed">
        <parent link="base_link"/>
        <child link="base_footprint"/>
        <origin xyz="0.0 0.0 -0.075" rpy="0 0 0"/>
    </joint>

    <!-- front right wheel -->
    <link name="wheel_front_right">
        <inertial>
            <mass value="2"/>
            <inertia ixx="1e-3" ixy="0.0" ixz="0" iyy="1e-3" iyz="0" izz="1e-3"/>
        </inertial>
        <visual>
            <geometry>
                <cylinder radius="0.075" length="0.05"/>
            </geometry>
            <material name="whtie">
                <color rgba="1 1 1 1"/>
            </material>
        </visual>
        <collision>
            <geometry>
                <cylinder radius="0.075" length="0.05"/>
            </geometry>
            <contact_coefficients mu="1" kp="1e+13" kd="1.0"/>
        </collision>
    </link>

    <joint name="wheel_front_right_joint" type="continuous">
        <origin xyz="0.125 0.2 0.0" rpy="1.57 0.0 0.0"/>
        <parent link="base_link"/>
        <child link="wheel_front_right"/>
        <axis xyz="0.0 0.0 1.0"/>
    </joint>

    <!-- front left wheel -->
    <link name="wheel_front_left">
        <inertial>
            <mass value="2"/>
            <inertia ixx="1e-3" ixy="0.0" ixz="0" iyy="1e-3" iyz="0" izz="1e-3"/>
        </inertial>
        <visual>
            <geometry>
                <cylinder radius="0.075" length="0.05"/>
            </geometry>
            <material name="whtie">
                <color rgba="1 1 1 1"/>
            </material>
        </visual>
        <collision>
            <geometry>
                <cylinder radius="0.075" length="0.05"/>
            </geometry>
            <contact_coefficients mu="1" kp="1e+13" kd="1.0"/>
        </collision>
    </link>

    <joint name="wheel_front_left_joint" type="continuous">
        <origin xyz="0.125 -0.2 0.0" rpy="1.57 0.0 0.0"/>
        <parent link="base_link"/>
        <child link="wheel_front_left"/>
        <axis xyz="0.0 0.0 1.0"/>
    </joint>

    <!-- Caster wheel -->
    <link name="front_caster">
        <visual>
            <geometry>
                <sphere radius="0.075"/>
            </geometry>
            <material name="Cyan">
                <color rgba="0 1.0 1.0 1.0"/>
            </material>
        </visual>
        <collision>
            <geometry>
                <sphere radius="0.075"/>
            </geometry>
        </collision>
    </link>

    <joint name="caster_joint" type="fixed">
        <parent link="base_link"/>
        <child link="front_caster"/>
        <origin xyz="-0.15 0.0 0" rpy="0 0 0"/>
    </joint>

    <!-- Camera -->
    <link name="camera_link">
        <inertial>
            <mass value="0.5"/>
            <inertia ixx="0.01" ixy="0.0" ixz="0" iyy="0.01" iyz="0" izz="0.01"/>
        </inertial>
        <visual>
            <geometry>
                <box size="0.05 0.25 0.1"/>
            </geometry>
            <material name="blue">
                <color rgba="0 0 1 1"/>
            </material>
        </visual>
    </link>

    <joint name="camera_joint" type="fixed">
        <origin xyz="-0.175 0 0.1" rpy="0 0.0 3.14"/>
        <parent link="base_link"/>
        <child link="camera_link"/>
        <axis xyz="0.0 0.0 1.0"/>
    </joint>

    <!-- LiDAR -->
    <link name="lidar_link">
        <inertial>
            <mass value="0.5"/>
            <inertia ixx="0.01" ixy="0.0" ixz="0" iyy="0.01" iyz="0" izz="0.01"/>
        </inertial>
        <visual>
            <geometry>
                <cylinder radius="0.05" length="0.05"/>
            </geometry>
            <material name="red">
                <color rgba="1 0 0 0.7"/>
            </material>
        </visual>
    </link>

    <joint name="lidar_joint" type="fixed">
        <origin xyz="-0.215 0 0.0" rpy="0 0.0 1.57"/>
        <parent link="base_link"/>
        <child link="lidar_link"/>
        <axis xyz="0.0 0.0 1.0"/>
    </joint>

    <!-- IMU -->
    <link name="imu_link">
        <visual>
            <inertial>
                <mass value="0.3"/>
                <inertia ixx="0.01" ixy="0.0" ixz="0" iyy="0.01" iyz="0" izz="0.01"/>
            </inertial>
            <geometry>
                <box size="0.05 0.05 0.05"/>
            </geometry>
            <material name="green">
                <color rgba="0 1 0 0.7"/>
            </material>
        </visual>
        <collision>
            <geometry>
                <box size="0.05 0.05 0.05"/>
            </geometry>
        </collision>
    </link>

    <joint name="imu_joint" type="fixed">
        <origin xyz="0 0 0.075" rpy="0 0 0"/>
        <parent link="base_link"/>
        <child link="imu_link"/>
        <axis xyz="0 0 1.0"/>
    </joint>
</robot>
